Watching for file changes with StatReloader
Not Found: /
[21/Sep/2020 20:23:23] "GET / HTTP/1.1" 404 2026
Not Found: /
[21/Sep/2020 20:23:25] "GET / HTTP/1.1" 404 2026
Not Found: /
[21/Sep/2020 20:23:25] "GET / HTTP/1.1" 404 2026
Not Found: /
[21/Sep/2020 20:23:26] "GET / HTTP/1.1" 404 2026
Not Found: /
[21/Sep/2020 20:24:00] "GET / HTTP/1.1" 404 2026
Not Found: /
[21/Sep/2020 20:24:38] "GET / HTTP/1.1" 404 2026
Not Found: /
[21/Sep/2020 20:24:39] "GET / HTTP/1.1" 404 2026
Not Found: /
[21/Sep/2020 20:24:39] "GET / HTTP/1.1" 404 2026
Not Found: /
[21/Sep/2020 20:25:04] "GET / HTTP/1.1" 404 2026
Not Found: /
[21/Sep/2020 20:25:05] "GET / HTTP/1.1" 404 2026
/var/www/community/app/urls.py changed, reloading.
Performing system checks...

System check identified no issues (0 silenced).
September 21, 2020 - 20:23:18
Django version 3.1.1, using settings 'app.settings'
Starting development server at http://0.0.0.0:3000/
Quit the server with CONTROL-C.
Watching for file changes with StatReloader
Exception in thread django-main-thread:
Traceback (most recent call last):
  File "/usr/lib/python3.6/threading.py", line 916, in _bootstrap_inner
    self.run()
  File "/usr/lib/python3.6/threading.py", line 864, in run
    self._target(*self._args, **self._kwargs)
  File "/var/www/community/myvenv/lib/python3.6/site-packages/django/utils/autoreload.py", line 53, in wrapper
    fn(*args, **kwargs)
  File "/var/www/community/myvenv/lib/python3.6/site-packages/django/core/management/commands/runserver.py", line 118, in inner_run
    self.check(display_num_errors=True)
  File "/var/www/community/myvenv/lib/python3.6/site-packages/django/core/management/base.py", line 396, in check
    databases=databases,
  File "/var/www/community/myvenv/lib/python3.6/site-packages/django/core/checks/registry.py", line 70, in run_checks
    new_errors = check(app_configs=app_configs, databases=databases)
  File "/var/www/community/myvenv/lib/python3.6/site-packages/django/core/checks/urls.py", line 13, in check_url_config
    return check_resolver(resolver)
  File "/var/www/community/myvenv/lib/python3.6/site-packages/django/core/checks/urls.py", line 23, in check_resolver
    return check_method()
  File "/var/www/community/myvenv/lib/python3.6/site-packages/django/urls/resolvers.py", line 408, in check
    for pattern in self.url_patterns:
  File "/var/www/community/myvenv/lib/python3.6/site-packages/django/utils/functional.py", line 48, in __get__
    res = instance.__dict__[self.name] = self.func(instance)
  File "/var/www/community/myvenv/lib/python3.6/site-packages/django/urls/resolvers.py", line 589, in url_patterns
    patterns = getattr(self.urlconf_module, "urlpatterns", self.urlconf_module)
  File "/var/www/community/myvenv/lib/python3.6/site-packages/django/utils/functional.py", line 48, in __get__
    res = instance.__dict__[self.name] = self.func(instance)
  File "/var/www/community/myvenv/lib/python3.6/site-packages/django/urls/resolvers.py", line 582, in urlconf_module
    return import_module(self.urlconf_name)
  File "/usr/lib/python3.6/importlib/__init__.py", line 126, in import_module
    return _bootstrap._gcd_import(name[level:], package, level)
  File "<frozen importlib._bootstrap>", line 994, in _gcd_import
  File "<frozen importlib._bootstrap>", line 971, in _find_and_load
  File "<frozen importlib._bootstrap>", line 955, in _find_and_load_unlocked
  File "<frozen importlib._bootstrap>", line 665, in _load_unlocked
  File "<frozen importlib._bootstrap_external>", line 678, in exec_module
  File "<frozen importlib._bootstrap>", line 219, in _call_with_frames_removed
  File "/var/www/community/app/urls.py", line 18, in <module>
    from home import views
ModuleNotFoundError: No module named 'home'

/var/www/community/app/urls.py changed, reloading.
Performing system checks...

Watching for file changes with StatReloader
